Workbook

Sheet {worksheet}
A1: 2026-07-09 16:30:22
A2: No. | B2: 거래처 관리코드 | C2: Site | D2: 창고 | E2: 출고일 | F2: 등록자 | G2: 거래처 | H2: 거래처 약칭 | I2: 국가 | J2: Biz Type | K2: 상품코드 | L2: 상품명 | M2: 브랜드 | N2: Curr | O2: 수량 | P2: 판매단가 | Q2: 금액 | R2: VAT | S2: 환산금액 | T2: 평균단가 | U2: 마진율 적용 | V2: 판매이익 | W2: 사용 목적 | X2: % | Y2: Invoice No | AA2: Month | AB2: Period | AC2: Revenue_KRW | AD2: Qty_num | AE2: Profit_KRW | AF2: Type
A3: 1 | B3: 06312 | C3: KR | D3: KR-W | E3: 2025-09-05 | F3: diane | G3: MOARS | I3: Netherlands The | J3: KR-OVERSEAS | K3: PYS13-A | L3: (변경예정) 얼티밋 진정 솔루션 앰플 30ml | M3: 편강율 | N3: USD | O3: 4,050 | P3: 0.00 | Q3: 0.00 | R3: 0.00 | S3: 0.00 | T3: 0.00 | U3: 0.00 | V3: 0.00 | W3: 상품 샘플링 (견본,무상증정) | X3: 0.0 | Y3: IN00369756 | AA3: =LEFT(E3,7) -> 2025-09 | AB3: =IF(AND($AA3>="2025-01",$AA3<="2025-06"),"H1_2025",IF(AND($AA3>="2026-01",$AA3<="2026-06"),"H1_2026","")) | AC3: =IFERROR(VALUE(SUBSTITUTE(S3,",","")),0) -> 0 | AD3: =IFERROR(VALUE(SUBSTITUTE(O3,",","")),0) -> 4050 | AE3: =IFERROR(VALUE(SUBSTITUTE(V3,",","")),0) -> 0 | AF3: =IF(ISNUMBER(SEARCH("FOC",W3)),"FOC",IF(ISNUMBER(SEARCH("샘플",W3)),"Sample","Paid")) -> Sample
A4: 2 | B4: 06312 | C4: KR | D4: KR-W | E4: 2025-06-19 | F4: diane | G4: MOARS | I4: Netherlands The | J4: KR-OVERSEAS | K4: PRS02-CSU | L4: (통합) 원더 릴리프 센텔라 세럼 언센티드 60ml | M4: 퓨리토 서울 | N4: USD | O4: 11 | P4: 0.00 | Q4: 0.00 | R4: 0.00 | S4: 0.00 | T4: 0.00 | U4: 0.00 | V4: 0.00 | W4: 상품 샘플링 (견본,무상증정) | X4: 0.0 | Y4: IN00349310 | AA4: =LEFT(E4,7) -> 2025-06 | AB4: =IF(AND($AA4>="2025-01",$AA4<="2025-06"),"H1_2025",IF(AND($AA4>="2026-01",$AA4<="2026-06"),"H1_2026","")) -> H1_2025 | AC4: =IFERROR(VALUE(SUBSTITUTE(S4,",","")),0) -> 0 | AD4: =IFERROR(VALUE(SUBSTITUTE(O4,",","")),0) -> 11 | AE4: =IFERROR(VALUE(SUBSTITUTE(V4,",","")),0) -> 0 | AF4: =IF(ISNUMBER(SEARCH("FOC",W4)),"FOC",IF(ISNUMBER(SEARCH("샘플",W4)),"Sample","Paid")) -> Sample
A5: 3 | B5: 06312 | C5: KR | D5: KR-W | E5: 2025-06-19 | F5: diane | G5: MOARS | I5: Netherlands The | J5: KR-OVERSEAS | K5: PRS04-CREU | L5: (통합) 마이티 밤부 판테놀 크림 100ml | M5: 퓨리토 서울 | N5: USD | O5: 11 | P5: 0.00 | Q5: 0.00 | R5: 0.00 | S5: 0.00 | T5: 0.00 | U5: 0.00 | V5: 0.00 | W5: 상품 샘플링 (견본,무상증정) | X5: 0.0 | Y5: IN00349310 | AA5: =LEFT(E5,7) -> 2025-06 | AB5: =IF(AND($AA5>="2025-01",$AA5<="2025-06"),"H1_2025",IF(AND($AA5>="2026-01",$AA5<="2026-06"),"H1_2026","")) -> H1_2025 | AC5: =IFERROR(VALUE(SUBSTITUTE(S5,",","")),0) -> 0 | AD5: =IFERROR(VALUE(SUBSTITUTE(O5,",","")),0) -> 11 | AE5: =IFERROR(VALUE(SUBSTITUTE(V5,",","")),0) -> 0 | AF5: =IF(ISNUMBER(SEARCH("FOC",W5)),"FOC",IF(ISNUMBER(SEARCH("샘플",W5)),"Sample","Paid")) -> Sample
A6: 4 | B6: 06312 | C6: KR | D6: KR-W | E6: 2025-06-19 | F6: diane | G6: MOARS | I6: Netherlands The | J6: KR-OVERSEAS | K6: PRS04-SETM | L6: (미조립) 세일즈 PR 박스 | M6: 퓨리토 서울 | N6: USD | O6: 11 | P6: 0.00 | Q6: 0.00 | R6: 0.00 | S6: 0.00 | T6: 0.00 | U6: 0.00 | V6: 0.00 | W6: 상품 샘플링 (견본,무상증정) | X6: 0.0 | Y6: IN00349310 | AA6: =LEFT(E6,7) -> 2025-06 | AB6: =IF(AND($AA6>="2025-01",$AA6<="2025-06"),"H1_2025",IF(AND($AA6>="2026-01",$AA6<="2026-06"),"H1_2026","")) -> H1_2025 | AC6: =IFERROR(VALUE(SUBSTITUTE(S6,",","")),0) -> 0 | AD6: =IFERROR(VALUE(SUBSTITUTE(O6,",","")),0) -> 11 | AE6: =IFERROR(VALUE(SUBSTITUTE(V6,",","")),0) -> 0 | AF6: =IF(ISNUMBER(SEARCH("FOC",W6)),"FOC",IF(ISNUMBER(SEARCH("샘플",W6)),"Sample","Paid")) -> Sample
A7: 5 | B7: 06312 | C7: KR | D7: KR-W | E7: 2025-06-19 | F7: diane | G7: MOARS | I7: Netherlands The | J7: KR-OVERSEAS | K7: PRS07-GELR | L7: (Renewal/통합) 오트 인 카밍 젤 크림 100ml | M7: 퓨리토 서울 | N7: USD | O7: 11 | P7: 0.00 | Q7: 0.00 | R7: 0.00 | S7: 0.00 | T7: 0.00 | U7: 0.00 | V7: 0.00 | W7: 상품 샘플링 (견본,무상증정) | X7: 0.0 | Y7: IN00349310 | AA7: =LEFT(E7,7) -> 2025-06 | AB7: =IF(AND($AA7>="2025-01",$AA7<="2025-06"),"H1_2025",IF(AND($AA7>="2026-01",$AA7<="2026-06"),"H1_2026","")) -> H1_2025 | AC7: =IFERROR(VALUE(SUBSTITUTE(S7,",","")),0) -> 0 | AD7: =IFERROR(VALUE(SUBSTITUTE(O7,",","")),0) -> 11 | AE7: =IFERROR(VALUE(SUBSTITUTE(V7,",","")),0) -> 0 | AF7: =IF(ISNUMBER(SEARCH("FOC",W7)),"FOC",IF(ISNUMBER(SEARCH("샘플",W7)),"Sample","Paid")) -> Sample
A8: 6 | B8: 06312 | C8: KR | D8: KR-W | E8: 2025-06-19 | F8: diane | G8: MOARS | I8: Netherlands The | J8: KR-OVERSEAS | K8: PRSM13-SC | L8: (PRSM13-SCREU) 데일리 소프트 터치 선크림 60ml | M8: 퓨리토 서울 | N8: USD | O8: 11 | P8: 0.00 | Q8: 0.00 | R8: 0.00 | S8: 0.00 | T8: 0.00 | U8: 0.00 | V8: 0.00 | W8: 상품 샘플링 (견본,무상증정) | X8: 0.0 | Y8: IN00349310 | AA8: =LEFT(E8,7) -> 2025-06 | AB8: =IF(AND($AA8>="2025-01",$AA8<="2025-06"),"H1_2025",IF(AND($AA8>="2026-01",$AA8<="2026-06"),"H1_2026","")) -> H1_2025 | AC8: =IFERROR(VALUE(SUBSTITUTE(S8,",","")),0) -> 0 | AD8: =IFERROR(VALUE(SUBSTITUTE(O8,",","")),0) -> 11 | AE8: =IFERROR(VALUE(SUBSTITUTE(V8,",","")),0) -> 0 | AF8: =IF(ISNUMBER(SEARCH("FOC",W8)),"FOC",IF(ISNUMBER(SEARCH("샘플",W8)),"Sample","Paid")) -> Sample
A9: 7 | B9: 06312 | C9: KR | D9: KR-W | E9: 2025-06-19 | F9: diane | G9: MOARS | I9: Netherlands The | J9: KR-OVERSEAS | K9: PRSM13-ST | L9: (통합) 데일리 소프트 터치 선스틱 20g | M9: 퓨리토 서울 | N9: USD | O9: 11 | P9: 0.00 | Q9: 0.00 | R9: 0.00 | S9: 0.00 | T9: 0.00 | U9: 0.00 | V9: 0.00 | W9: 상품 샘플링 (견본,무상증정) | X9: 0.0 | Y9: IN00349310 | AA9: =LEFT(E9,7) -> 2025-06 | AB9: =IF(AND($AA9>="2025-01",$AA9<="2025-06"),"H1_2025",IF(AND($AA9>="2026-01",$AA9<="2026-06"),"H1_2026","")) -> H1_2025 | AC9: =IFERROR(VALUE(SUBSTITUTE(S9,",","")),0) -> 0 | AD9: =IFERROR(VALUE(SUBSTITUTE(O9,",","")),0) -> 11 | AE9: =IFERROR(VALUE(SUBSTITUTE(V9,",","")),0) -> 0 | AF9: =IF(ISNUMBER(SEARCH("FOC",W9)),"FOC",IF(ISNUMBER(SEARCH("샘플",W9)),"Sample","Paid")) -> Sample
A10: 8 | B10: 06312 | C10: KR | D10: KR-W | E10: 2025-06-05 | F10: diane | G10: MOARS | I10: Netherlands The | J10: KR-OVERSEAS | K10: HMCM1-DSSM | L10: (리뉴얼) 데일리즘 스머지 스탑 마스카라 컬링 블랙 | M10: 헤이미쉬 | N10: USD | O10: 2,000 | P10: 0.00 | Q10: 0.00 | R10: 0.00 | S10: 0.00 | T10: 36.91 | U10: 73,820.00 | V10: -73,820.00 | W10: 상품 샘플링 (견본,무상증정) | X10: 0.0 | Y10: IN00345465 | AA10: =LEFT(E10,7) -> 2025-06 | AB10: =IF(AND($AA10>="2025-01",$AA10<="2025-06"),"H1_2025",IF(AND($AA10>="2026-01",$AA10<="2026-06"),"H1_2026","")) -> H1_2025 | AC10: =IFERROR(VALUE(SUBSTITUTE(S10,",","")),0) -> 0 | AD10: =IFERROR(VALUE(SUBSTITUTE(O10,",","")),0) -> 2000 | AE10: =IFERROR(VALUE(SUBSTITUTE(V10,",","")),0) -> -73820 | AF10: =IF(ISNUMBER(SEARCH("FOC",W10)),"FOC",IF(ISNUMBER(SEARCH("샘플",W10)),"Sample","Paid")) -> Sample
A11: 9 | B11: 06312 | C11: KR | D11: KR-W | E11: 2025-06-05 | F11: diane | G11: MOARS | I11: Netherlands The | J11: KR-OVERSEAS | K11: PRS04-C | L11: 마이티 밤부 판테놀 크림 100ml | M11: 퓨리토 서울 | N11: USD | O11: 2,000 | P11: 0.00 | Q11: 0.00 | R11: 0.00 | S11: 0.00 | T11: 0.00 | U11: 0.00 | V11: 0.00 | W11: 상품 샘플링 (견본,무상증정) | X11: 0.0 | Y11: IN00345465 | AA11: =LEFT(E11,7) -> 2025-06 | AB11: =IF(AND($AA11>="2025-01",$AA11<="2025-06"),"H1_2025",IF(AND($AA11>="2026-01",$AA11<="2026-06"),"H1_2026","")) -> H1_2025 | AC11: =IFERROR(VALUE(SUBSTITUTE(S11,",","")),0) -> 0 | AD11: =IFERROR(VALUE(SUBSTITUTE(O11,",","")),0) -> 2000 | AE11: =IFERROR(VALUE(SUBSTITUTE(V11,",","")),0) -> 0 | AF11: =IF(ISNUMBER(SEARCH("FOC",W11)),"FOC",IF(ISNUMBER(SEARCH("샘플",W11)),"Sample","Paid")) -> Sample
A12: 10 | B12: 06312 | C12: KR | D12: KR-W | E12: 2025-06-05 | F12: diane | G12: MOARS | I12: Netherlands The | J12: KR-OVERSEAS | K12: PYS01-oilR | L12: [수묵화] 레디언스 페이스 오일 26ml (전: 리뉴얼 오일 26ml) | M12: 편강율 | N12: USD | O12: 2,000 | P12: 0.00 | Q12: 0.00 | R12: 0.00 | S12: 0.00 | T12: 0.00 | U12: 0.00 | V12: 0.00 | W12: 상품 샘플링 (견본,무상증정) | X12: 0.0 | Y12: IN00345465 | AA12: =LEFT(E12,7) -> 2025-06 | AB12: =IF(AND($AA12>="2025-01",$AA12<="2025-06"),"H1_2025",IF(AND($AA12>="2026-01",$AA12<="2026-06"),"H1_2026","")) -> H1_2025 | AC12: =IFERROR(VALUE(SUBSTITUTE(S12,",","")),0) -> 0 | AD12: =IFERROR(VALUE(SUBSTITUTE(O12,",","")),0) -> 2000 | AE12: =IFERROR(VALUE(SUBSTITUTE(V12,",","")),0) -> 0 | AF12: =IF(ISNUMBER(SEARCH("FOC",W12)),"FOC",IF(ISNUMBER(SEARCH("샘플",W12)),"Sample","Paid")) -> Sample
A13: 11 | B13: 06312 | C13: KR | D13: KR-W | E13: 2025-06-05 | F13: diane | G13: MOARS | I13: Netherlands The | J13: KR-OVERSEAS | K13: RLC01-CLRR | L13: *리뉴얼 1025 독도 클렌져_150ml (본품) | M13: 라운드랩 | N13: USD | O13: 2,000 | P13: 0.00 | Q13: 0.00 | R13: 0.00 | S13: 0.00 | T13: 0.00 | U13: 0.00 | V13: 0.00 | W13: 상품 샘플링 (견본,무상증정) | X13: 0.0 | Y13: IN00345465 | AA13: =LEFT(E13,7) -> 2025-06 | AB13: =IF(AND($AA13>="2025-01",$AA13<="2025-06"),"H1_2025",IF(AND($AA13>="2026-01",$AA13<="2026-06"),"H1_2026","")) -> H1_2025 | AC13: =IFERROR(VALUE(SUBSTITUTE(S13,",","")),0) -> 0 | AD13: =IFERROR(VALUE(SUBSTITUTE(O13,",","")),0) -> 2000 | AE13: =IFERROR(VALUE(SUBSTITUTE(V13,",","")),0) -> 0 | AF13: =IF(ISNUMBER(SEARCH("FOC",W13)),"FOC",IF(ISNUMBER(SEARCH("샘플",W13)),"Sample","Paid")) -> Sample
A14: 12 | B14: 06312 | C14: KR | D14: KR-W | E14: 2025-05-26 | F14: diane | G14: MOARS | I14: Netherlands The | J14: KR-OVERSEAS | K14: IUSM07-SCEU | L14: [EU] 센텔라 카밍 데일리 선크림 60ml | M14: 아이유닉 | N14: USD | O14: 1,220 | P14: 0.00 | Q14: 0.00 | R14: 0.00 | S14: 0.00 | T14: 0.00 | U14: 0.00 | V14: 0.00 | W14: 상품 샘플링 (견본,무상증정) | X14: 0.0 | Y14: IN00340192 | AA14: =LEFT(E14,7) -> 2025-05 | AB14: =IF(AND($AA14>="2025-01",$AA14<="2025-06"),"H1_2025",IF(AND($AA14>="2026-01",$AA14<="2026-06"),"H1_2026","")) -> H1_2025 | AC14: =IFERROR(VALUE(SUBSTITUTE(S14,",","")),0) -> 0 | AD14: =IFERROR(VALUE(SUBSTITUTE(O14,",","")),0) -> 1220 | AE14: =IFERROR(VALUE(SUBSTITUTE(V14,",","")),0) -> 0 | AF14: =IF(ISNUMBER(SEARCH("FOC",W14)),"FOC",IF(ISNUMBER(SEARCH("샘플",W14)),"Sample","Paid")) -> Sample
... A16: 14 | B16: 06312 | C16: KR | D16: OPO | E16: 2026-06-18 | F16: minju | G16: MOARS | I16: Netherlands The | J16: KR-OVERSEAS | K16: RjACM01-LEU | L16: [EU] 어드밴스드 PDRN 리쥬비네이팅 립 세럼 10ml | M16: 닥터 리쥬올 | N16: USD | O16: 24 | P16: 0.01 | Q16: 0.24 | R16: 0.00 | S16: 355.51 | T16: 5,600.00 | U16: 134,400.00 | V16: -134,044.49 | W16: FOC (Free of charge, 판매장려금) | X16: -37,704.6 | Y16: IN00447658 | AA16: =LEFT(E16,7) -> 2026-06 | AB16: =IF(AND($AA16>="2025-01",$AA16<="2025-06"),"H1_2025",IF(AND($AA16>="2026-01",$AA16<="2026-06"),"H1_2026","")) -> H1_2026 | AC16: =IFERROR(VALUE(SUBSTITUTE(S16,",","")),0) -> 355.51 | AD16: =IFERROR(VALUE(SUBSTITUTE(O16,",","")),0) -> 24 | AE16: =IFERROR(VALUE(SUBSTITUTE(V16,",","")),0) -> -134044.49 | AF16: =IF(ISNUMBER(SEARCH("FOC",W16)),"FOC",IF(ISNUMBER(SEARCH("샘플",W16)),"Sample","Paid")) -> FOC
A17: 15 | B17: 06312 | C17: KR | D17: OPO | E17: 2026-06-18 | F17: minju | G17: MOARS | I17: Netherlands The | J17: KR-OVERSEAS | K17: RjACM01-LEU | L17: [EU] 어드밴스드 PDRN 리쥬비네이팅 립 세럼 10ml | M17: 닥터 리쥬올 | N17: USD | O17: 240 | P17: 5.83 | Q17: 1,399.20 | R17: 0.00 | S17: 2,072,634.96 | T17: 5,600.00 | U17: 1,344,000.00 | V17: 728,634.96 | X17: 35.2 | Y17: IN00447658 | AA17: =LEFT(E17,7) -> 2026-06 | AB17: =IF(AND($AA17>="2025-01",$AA17<="2025-06"),"H1_2025",IF(AND($AA17>="2026-01",$AA17<="2026-06"),"H1_2026","")) -> H1_2026 | AC17: =IFERROR(VALUE(SUBSTITUTE(S17,",","")),0) -> 2072635 | AD17: =IFERROR(VALUE(SUBSTITUTE(O17,",","")),0) -> 240 | AE17: =IFERROR(VALUE(SUBSTITUTE(V17,",","")),0) -> 728634.96 | AF17: =IF(ISNUMBER(SEARCH("FOC",W17)),"FOC",IF(ISNUMBER(SEARCH("샘플",W17)),"Sample","Paid")) -> Paid
A18: 16 | B18: 06312 | C18: KR | D18: OPO | E18: 2026-06-18 | F18: minju | G18: MOARS | I18: Netherlands The | J18: KR-OVERSEAS | K18: RjAP01-MEU | L18: [EU][4매입] 어드밴스드 PDRN 리쥬비네이팅 마스크 | M18: 닥터 리쥬올 | N18: USD | O18: 4 | P18: 0.01 | Q18: 0.04 | R18: 0.00 | S18: 59.25 | T18: 6,300.00 | U18: 25,200.00 | V18: -25,140.75 | W18: FOC (Free of charge, 판매장려금) | X18: -42,430.2 | Y18: IN00447658 | AA18: =LEFT(E18,7) -> 2026-06 | AB18: =IF(AND($AA18>="2025-01",$AA18<="2025-06"),"H1_2025",IF(AND($AA18>="2026-01",$AA18<="2026-06"),"H1_2026","")) -> H1_2026 | AC18: =IFERROR(VALUE(SUBSTITUTE(S18,",","")),0) -> 59.25 | AD18: =IFERROR(VALUE(SUBSTITUTE(O18,",","")),0) -> 4 | AE18: =IFERROR(VALUE(SUBSTITUTE(V18,",","")),0) -> -25140.75 | AF18: =IF(ISNUMBER(SEARCH("FOC",W18)),"FOC",IF(ISNUMBER(SEARCH("샘플",W18)),"Sample","Paid")) -> FOC
A19: 17 | B19: 06312 | C19: KR | D19: OPO | E19: 2026-06-18 | F19: minju | G19: MOARS | I19: Netherlands The | J19: KR-OVERSEAS | K19: RjAP01-MEU | L19: [EU][4매입] 어드밴스드 PDRN 리쥬비네이팅 마스크 | M19: 닥터 리쥬올 | N19: USD | O19: 40 | P19: 7.29 | Q19: 291.60 | R19: 0.00 | S19: 431,947.08 | T19: 6,300.00 | U19: 252,000.00 | V19: 179,947.08 | X19: 41.7 | Y19: IN00447658 | AA19: =LEFT(E19,7) -> 2026-06 | AB19: =IF(AND($AA19>="2025-01",$AA19<="2025-06"),"H1_2025",IF(AND($AA19>="2026-01",$AA19<="2026-06"),"H1_2026","")) -> H1_2026 | AC19: =IFERROR(VALUE(SUBSTITUTE(S19,",","")),0) -> 431947.08 | AD19: =IFERROR(VALUE(SUBSTITUTE(O19,",","")),0) -> 40 | AE19: =IFERROR(VALUE(SUBSTITUTE(V19,",","")),0) -> 179947.08 | AF19: =IF(ISNUMBER(SEARCH("FOC",W19)),"FOC",IF(ISNUMBER(SEARCH("샘플",W19)),"Sample","Paid")) -> Paid
A20: 18 | B20: 06312 | C20: KR | D20: OPO | E20: 2026-06-18 | F20: minju | G20: MOARS | I20: Netherlands The | J20: KR-OVERSEAS | K20: RjAS01-CLC | L20: 어드벤스드 LC-세라마이드 베리어 크림 50ml | M20: 닥터 리쥬올 | N20: USD | O20: 30 | P20: 0.01 | Q20: 0.30 | R20: 0.00 | S20: 444.39 | T20: 15,000.00 | U20: 450,000.00 | V20: -449,555.61 | W20: FOC (Free of charge, 판매장려금) | X20: -101,162.4 | Y20: IN00447658 | AA20: =LEFT(E20,7) -> 2026-06 | AB20: =IF(AND($AA20>="2025-01",$AA20<="2025-06"),"H1_2025",IF(AND($AA20>="2026-01",$AA20<="2026-06"),"H1_2026","")) -> H1_2026 | AC20: =IFERROR(VALUE(SUBSTITUTE(S20,",","")),0) -> 444.39 | AD20: =IFERROR(VALUE(SUBSTITUTE(O20,",","")),0) -> 30 | AE20: =IFERROR(VALUE(SUBSTITUTE(V20,",","")),0) -> -449555.61 | AF20: =IF(ISNUMBER(SEARCH("FOC",W20)),"FOC",IF(ISNUMBER(SEARCH("샘플",W20)),"Sample","Paid")) -> FOC
A21: 19 | B21: 06312 | C21: KR | D21: OPO | E21: 2026-06-18 | F21: minju | G21: MOARS | I21: Netherlands The | J21: KR-OVERSEAS | K21: RjAS01-CLC | L21: 어드벤스드 LC-세라마이드 베리어 크림 50ml | M21: 닥터 리쥬올 | N21: USD | O21: 300 | P21: 12.58 | Q21: 3,774.00 | R21: 0.00 | S21: 5,590,426.20 | T21: 15,000.00 | U21: 4,500,000.00 | V21: 1,090,426.20 | X21: 19.5 | Y21: IN00447658 | AA21: =LEFT(E21,7) -> 2026-06 | AB21: =IF(AND($AA21>="2025-01",$AA21<="2025-06"),"H1_2025",IF(AND($AA21>="2026-01",$AA21<="2026-06"),"H1_2026","")) -> H1_2026 | AC21: =IFERROR(VALUE(SUBSTITUTE(S21,",","")),0) -> 5590426.2 | AD21: =IFERROR(VALUE(SUBSTITUTE(O21,",","")),0) -> 300 | AE21: =IFERROR(VALUE(SUBSTITUTE(V21,",","")),0) -> 1090426.2 | AF21: =IF(ISNUMBER(SEARCH("FOC",W21)),"FOC",IF(ISNUMBER(SEARCH("샘플",W21)),"Sample","Paid")) -> Paid
A22: 20 | B22: 06312 | C22: KR | D22: OPO | E22: 2026-06-18 | F22: minju | G22: MOARS | I22: Netherlands The | J22: KR-OVERSEAS | K22: RjAS01-CREU | L22: [EU] 어드밴스드 PDRN 크림 20ml | M22: 닥터 리쥬올 | N22: USD | O22: 80 | P22: 0.01 | Q22: 0.80 | R22: 0.00 | S22: 1,185.04 | T22: 11,250.00 | U22: 900,000.00 | V22: -898,814.96 | W22: FOC (Free of charge, 판매장려금) | X22: -75,846.8 | Y22: IN00447658 | AA22: =LEFT(E22,7) -> 2026-06 | AB22: =IF(AND($AA22>="2025-01",$AA22<="2025-06"),"H1_2025",IF(AND($AA22>="2026-01",$AA22<="2026-06"),"H1_2026","")) -> H1_2026 | AC22: =IFERROR(VALUE(SUBSTITUTE(S22,",","")),0) -> 1185.04 | AD22: =IFERROR(VALUE(SUBSTITUTE(O22,",","")),0) -> 80 | AE22: =IFERROR(VALUE(SUBSTITUTE(V22,",","")),0) -> -898814.96 | AF22: =IF(ISNUMBER(SEARCH("FOC",W22)),"FOC",IF(ISNUMBER(SEARCH("샘플",W22)),"Sample","Paid")) -> FOC
A23: 21 | B23: 06312 | C23: KR | D23: OPO | E23: 2026-06-18 | F23: minju | G23: MOARS | I23: Netherlands The | J23: KR-OVERSEAS | K23: RjAS01-CREU | L23: [EU] 어드밴스드 PDRN 크림 20ml | M23: 닥터 리쥬올 | N23: USD | O23: 800 | P23: 13.30 | Q23: 10,640.00 | R23: 0.00 | S23: 15,761,032.00 | T23: 11,250.00 | U23: 9,000,000.00 | V23: 6,761,032.00 | X23: 42.9 | Y23: IN00447658 | AA23: =LEFT(E23,7) -> 2026-06 | AB23: =IF(AND($AA23>="2025-01",$AA23<="2025-06"),"H1_2025",IF(AND($AA23>="2026-01",$AA23<="2026-06"),"H1_2026","")) -> H1_2026 | AC23: =IFERROR(VALUE(SUBSTITUTE(S23,",","")),0) -> 15761032 | AD23: =IFERROR(VALUE(SUBSTITUTE(O23,",","")),0) -> 800 | AE23: =IFERROR(VALUE(SUBSTITUTE(V23,",","")),0) -> 6761032 | AF23: =IF(ISNUMBER(SEARCH("FOC",W23)),"FOC",IF(ISNUMBER(SEARCH("샘플",W23)),"Sample","Paid")) -> Paid
A24: 22 | B24: 06312 | C24: KR | D24: OPO | E24: 2026-06-18 | F24: minju | G24: MOARS | I24: Netherlands The | J24: KR-OVERSEAS | K24: RjAS01-CRMEU | L24: [EU] 어드밴스드 PDRN 크림 60ml | M24: 닥터 리쥬올 | N24: USD | O24: 400 | P24: 35.47 | Q24: 14,188.00 | R24: 0.00 | S24: 21,016,684.40 | T24: 32,000.00 | U24: 12,800,000.00 | V24: 8,216,684.40 | X24: 39.1 | Y24: IN00447658 | AA24: =LEFT(E24,7) -> 2026-06 | AB24: =IF(AND($AA24>="2025-01",$AA24<="2025-06"),"H1_2025",IF(AND($AA24>="2026-01",$AA24<="2026-06"),"H1_2026","")) -> H1_2026 | AC24: =IFERROR(VALUE(SUBSTITUTE(S24,",","")),0) -> 21016684 | AD24: =IFERROR(VALUE(SUBSTITUTE(O24,",","")),0) -> 400 | AE24: =IFERROR(VALUE(SUBSTITUTE(V24,",","")),0) -> 8216684.4 | AF24: =IF(ISNUMBER(SEARCH("FOC",W24)),"FOC",IF(ISNUMBER(SEARCH("샘플",W24)),"Sample","Paid")) -> Paid
A25: 23 | B25: 06312 | C25: KR | D25: OPO | E25: 2026-06-18 | F25: minju | G25: MOARS | I25: Netherlands The | J25: KR-OVERSEAS | K25: RjAS01-CRMEU | L25: [EU] 어드밴스드 PDRN 크림 60ml | M25: 닥터 리쥬올 | N25: USD | O25: 40 | P25: 0.01 | Q25: 0.40 | R25: 0.00 | S25: 592.52 | T25: 32,000.00 | U25: 1,280,000.00 | V25: -1,279,407.48 | W25: FOC (Free of charge, 판매장려금) | X25: -215,926.5 | Y25: IN00447658 | AA25: =LEFT(E25,7) -> 2026-06 | AB25: =IF(AND($AA25>="2025-01",$AA25<="2025-06"),"H1_2025",IF(AND($AA25>="2026-01",$AA25<="2026-06"),"H1_2026","")) -> H1_2026 | AC25: =IFERROR(VALUE(SUBSTITUTE(S25,",","")),0) -> 592.52 | AD25: =IFERROR(VALUE(SUBSTITUTE(O25,",","")),0) -> 40 | AE25: =IFERROR(VALUE(SUBSTITUTE(V25,",","")),0) -> -1279407.5 | AF25: =IF(ISNUMBER(SEARCH("FOC",W25)),"FOC",IF(ISNUMBER(SEARCH("샘플",W25)),"Sample","Paid")) -> FOC
A26: 24 | B26: 06312 | C26: KR | D26: OPO | E26: 2026-06-17 | F26: minju | G26: MOARS | I26: Netherlands The | J26: KR-OVERSEAS | K26: goodalS06-TPUS | L26: (글로벌) 청귤비타C 잡티 케어 패드 | M26: 구달 | N26: USD | O26: 24 | P26: 8.38 | Q26: 201.12 | R26: 0.00 | S26: 299,347.01 | T26: 9,454.55 | U26: 226,909.09 | V26: 72,437.92 | X26: 24.2 | Y26: IN00447659 | AA26: =LEFT(E26,7) -> 2026-06 | AB26: =IF(AND($AA26>="2025-01",$AA26<="2025-06"),"H1_2025",IF(AND($AA26>="2026-01",$AA26<="2026-06"),"H1_2026","")) -> H1_2026 | AC26: =IFERROR(VALUE(SUBSTITUTE(S26,",","")),0) -> 299347.01 | AD26: =IFERROR(VALUE(SUBSTITUTE(O26,",","")),0) -> 24 | AE26: =IFERROR(VALUE(SUBSTITUTE(V26,",","")),0) -> 72437.92 | AF26: =IF(ISNUMBER(SEARCH("FOC",W26)),"FOC",IF(ISNUMBER(SEARCH("샘플",W26)),"Sample","Paid")) -> Paid
A27: 25 | B27: 06312 | C27: KR | D27: OPO | E27: 2026-06-17 | F27: minju | G27: MOARS | I27: Netherlands The | J27: KR-OVERSEAS | K27: RjAS01-CLCEU | L27: [EU] 어드벤스드 LC-세라마이드 베리어 크림 50ml | M27: 닥터 리쥬올 | N27: USD | O27: 500 | P27: 12.58 | Q27: 6,290.00 | R27: 0.00 | S27: 9,362,036.00 | T27: 9,360.00 | U27: 4,680,000.00 | V27: 4,682,036.00 | X27: 50.0 | Y27: IN00447659 | AA27: =LEFT(E27,7) -> 2026-06 | AB27: =IF(AND($AA27>="2025-01",$AA27<="2025-06"),"H1_2025",IF(AND($AA27>="2026-01",$AA27<="2026-06"),"H1_2026","")) -> H1_2026 | AC27: =IFERROR(VALUE(SUBSTITUTE(S27,",","")),0) -> 9362036 | AD27: =IFERROR(VALUE(SUBSTITUTE(O27,",","")),0) -> 500 | AE27: =IFERROR(VALUE(SUBSTITUTE(V27,",","")),0) -> 4682036 | AF27: =IF(ISNUMBER(SEARCH("FOC",W27)),"FOC",IF(ISNUMBER(SEARCH("샘플",W27)),"Sample","Paid")) -> Paid
A28: 26 | B28: 06312 | C28: KR | D28: OPO | E28: 2026-06-17 | F28: minju | G28: MOARS | I28: Netherlands The | J28: KR-OVERSEAS | K28: RjAS01-CLCEU | L28: [EU] 어드벤스드 LC-세라마이드 베리어 크림 50ml | M28: 닥터 리쥬올 | N28: USD | O28: 50 | P28: 0.01 | Q28: 0.50 | R28: 0.00 | S28: 744.20 | T28: 9,360.00 | U28: 468,000.00 | V28: -467,255.80 | W28: FOC (Free of charge, 판매장려금) | X28: -62,786.3 | Y28: IN00447659 | AA28: =LEFT(E28,7) -> 2026-06 | AB28: =IF(AND($AA28>="2025-01",$AA28<="2025-06"),"H1_2025",IF(AND($AA28>="2026-01",$AA28<="2026-06"),"H1_2026","")) -> H1_2026 | AC28: =IFERROR(VALUE(SUBSTITUTE(S28,",","")),0) -> 744.2 | AD28: =IFERROR(VALUE(SUBSTITUTE(O28,",","")),0) -> 50 | AE28: =IFERROR(VALUE(SUBSTITUTE(V28,",","")),0) -> -467255.8 | AF28: =IF(ISNUMBER(SEARCH("FOC",W28)),"FOC",IF(ISNUMBER(SEARCH("샘플",W28)),"Sample","Paid")) -> FOC
A29: 27 | B29: 06312 | C29: KR | D29: OPO | E29: 2026-06-17 | F29: minju | G29: MOARS | I29: Netherlands The | J29: KR-OVERSEAS | K29: RjAS01-CREU | L29: [EU] 어드밴스드 PDRN 크림 20ml | M29: 닥터 리쥬올 | N29: USD | O29: 140 | P29: 0.01 | Q29: 1.40 | R29: 0.00 | S29: 2,083.76 | T29: 11,250.00 | U29: 1,575,000.00 | V29: -1,572,916.24 | W29: FOC (Free of charge, 판매장려금) | X29: -75,484.5 | Y29: IN00447659 | AA29: =LEFT(E29,7) -> 2026-06 | AB29: =IF(AND($AA29>="2025-01",$AA29<="2025-06"),"H1_2025",IF(AND($AA29>="2026-01",$AA29<="2026-06"),"H1_2026","")) -> H1_2026 | AC29: =IFERROR(VALUE(SUBSTITUTE(S29,",","")),0) -> 2083.76 | AD29: =IFERROR(VALUE(SUBSTITUTE(O29,",","")),0) -> 140 | AE29: =IFERROR(VALUE(SUBSTITUTE(V29,",","")),0) -> -1572916.2 | AF29: =IF(ISNUMBER(SEARCH("FOC",W29)),"FOC",IF(ISNUMBER(SEARCH("샘플",W29)),"Sample","Paid")) -> FOC
A30: 28 | B30: 06312 | C30: KR | D30: OPO | E30: 2026-06-17 | F30: minju | G30: MOARS | I30: Netherlands The | J30: KR-OVERSEAS | K30: RjAS01-CREU | L30: [EU] 어드밴스드 PDRN 크림 20ml | M30: 닥터 리쥬올 | N30: USD | O30: 1,400 | P30: 13.30 | Q30: 18,620.00 | R30: 0.00 | S30: 27,714,008.00 | T30: 11,250.00 | U30: 15,750,000.00 | V30: 11,964,008.00 | X30: 43.2 | Y30: IN00447659 | AA30: =LEFT(E30,7) -> 2026-06 | AB30: =IF(AND($AA30>="2025-01",$AA30<="2025-06"),"H1_2025",IF(AND($AA30>="2026-01",$AA30<="2026-06"),"H1_2026","")) -> H1_2026 | AC30: =IFERROR(VALUE(SUBSTITUTE(S30,",","")),0) -> 27714008 | AD30: =IFERROR(VALUE(SUBSTITUTE(O30,",","")),0) -> 1400 | AE30: =IFERROR(VALUE(SUBSTITUTE(V30,",","")),0) -> 11964008 | AF30: =IF(ISNUMBER(SEARCH("FOC",W30)),"FOC",IF(ISNUMBER(SEARCH("샘플",W30)),"Sample","Paid")) -> Paid
A31: 29 | B31: 06312 | C31: KR | D31: OPO | E31: 2026-06-17 | F31: minju | G31: MOARS | I31: Netherlands The | J31: KR-OVERSEAS | K31: RjAS01-CRMEU | L31: [EU] 어드밴스드 PDRN 크림 60ml | M31: 닥터 리쥬올 | N31: USD | O31: 80 | P31: 0.01 | Q31: 0.80 | R31: 0.00 | S31: 1,190.72 | T31: 32,000.00 | U31: 2,560,000.00 | V31: -2,558,809.28 | W31: FOC (Free of charge, 판매장려금) | X31: -214,896.0 | Y31: IN00447659 | AA31: =LEFT(E31,7) -> 2026-06 | AB31: =IF(AND($AA31>="2025-01",$AA31<="2025-06"),"H1_2025",IF(AND($AA31>="2026-01",$AA31<="2026-06"),"H1_2026","")) -> H1_2026 | AC31: =IFERROR(VALUE(SUBSTITUTE(S31,",","")),0) -> 1190.72 | AD31: =IFERROR(VALUE(SUBSTITUTE(O31,",","")),0) -> 80 | AE31: =IFERROR(VALUE(SUBSTITUTE(V31,",","")),0) -> -2558809.3 | AF31: =IF(ISNUMBER(SEARCH("FOC",W31)),"FOC",IF(ISNUMBER(SEARCH("샘플",W31)),"Sample","Paid")) -> FOC
A32: 30 | B32: 06312 | C32: KR | D32: OPO | E32: 2026-06-17 | F32: minju | G32: MOARS | I32: Netherlands The | J32: KR-OVERSEAS | K32: RjAS01-CRMEU | L32: [EU] 어드밴스드 PDRN 크림 60ml | M32: 닥터 리쥬올 | N32: USD | O32: 800 | P32: 35.47 | Q32: 28,376.00 | R32: 0.00 | S32: 42,234,838.40 | T32: 32,000.00 | U32: 25,600,000.00 | V32: 16,634,838.40 | X32: 39.4 | Y32: IN00447659 | AA32: =LEFT(E32,7) -> 2026-06 | AB32: =IF(AND($AA32>="2025-01",$AA32<="2025-06"),"H1_2025",IF(AND($AA32>="2026-01",$AA32<="2026-06"),"H1_2026","")) -> H1_2026 | AC32: =IFERROR(VALUE(SUBSTITUTE(S32,",","")),0) -> 42234838 | AD32: =IFERROR(VALUE(SUBSTITUTE(O32,",","")),0) -> 800 | AE32: =IFERROR(VALUE(SUBSTITUTE(V32,",","")),0) -> 16634838 | AF32: =IF(ISNUMBER(SEARCH("FOC",W32)),"FOC",IF(ISNUMBER(SEARCH("샘플",W32)),"Sample","Paid")) -> Paid
A33: 31 | B33: 06312 | C33: KR | D33: OPO | E33: 2026-06-17 | F33: minju | G33: MOARS | I33: Netherlands The | J33: KR-OVERSEAS | K33: RjAS01-SM | L33: 어드밴스드 레티노-멜라 세럼 30ml | M33: 닥터 리쥬올 | N33: USD | O33: 40 | P33: 0.01 | Q33: 0.40 | R33: 0.00 | S33: 595.36 | T33: 18,500.00 | U33: 740,000.00 | V33: -739,404.64 | W33: FOC (Free of charge, 판매장려금) | X33: -124,194.5 | Y33: IN00447659 | AA33: =LEFT(E33,7) -> 2026-06 | AB33: =IF(AND($AA33>="2025-01",$AA33<="2025-06"),"H1_2025",IF(AND($AA33>="2026-01",$AA33<="2026-06"),"H1_2026","")) -> H1_2026 | AC33: =IFERROR(VALUE(SUBSTITUTE(S33,",","")),0) -> 595.36 | AD33: =IFERROR(VALUE(SUBSTITUTE(O33,",","")),0) -> 40 | AE33: =IFERROR(VALUE(SUBSTITUTE(V33,",","")),0) -> -739404.64 | AF33: =IF(ISNUMBER(SEARCH("FOC",W33)),"FOC",IF(ISNUMBER(SEARCH("샘플",W33)),"Sample","Paid")) -> FOC
A34: 32 | B34: 06312 | C34: KR | D34: OPO | E34: 2026-06-17 | F34: minju | G34: MOARS | I34: Netherlands The | J34: KR-OVERSEAS | K34: RjAS01-SM | L34: 어드밴스드 레티노-멜라 세럼 30ml | M34: 닥터 리쥬올 | N34: USD | O34: 400 | P34: 15.48 | Q34: 6,192.00 | R34: 0.00 | S34: 9,216,172.80 | T34: 18,500.00 | U34: 7,400,000.00 | V34: 1,816,172.80 | X34: 19.7 | Y34: IN00447659 | AA34: =LEFT(E34,7) -> 2026-06 | AB34: =IF(AND($AA34>="2025-01",$AA34<="2025-06"),"H1_2025",IF(AND($AA34>="2026-01",$AA34<="2026-06"),"H1_2026","")) -> H1_2026 | AC34: =IFERROR(VALUE(SUBSTITUTE(S34,",","")),0) -> 9216172.8 | AD34: =IFERROR(VALUE(SUBSTITUTE(O34,",","")),0) -> 400 | AE34: =IFERROR(VALUE(SUBSTITUTE(V34,",","")),0) -> 1816172.8 | AF34: =IF(ISNUMBER(SEARCH("FOC",W34)),"FOC",IF(ISNUMBER(SEARCH("샘플",W34)),"Sample","Paid")) -> Paid
A35: 33 | B35: 06312 | C35: KR | D35: OPO | E35: 2026-06-16 | F35: minju | G35: MOARS | I35: Netherlands The | J35: KR-OVERSEAS | K35: ALSC01-Fbr | L35: (리뉴얼) 프레시 블루 히솝 라이스 모찌 클렌저 120g | M35: 아렌시아 | N35: USD | O35: 2 | P35: 6.24 | Q35: 12.48 | R35: 0.00 | S35: 18,389.28 | T35: 6,600.00 | U35: 13,200.00 | V35: 5,189.28 | X35: 28.2 | Y35: IN00444093 | AA35: =LEFT(E35,7) -> 2026-06 | AB35: =IF(AND($AA35>="2025-01",$AA35<="2025-06"),"H1_2025",IF(AND($AA35>="2026-01",$AA35<="2026-06"),"H1_2026","")) -> H1_2026 | AC35: =IFERROR(VALUE(SUBSTITUTE(S35,",","")),0) -> 18389.28 | AD35: =IFERROR(VALUE(SUBSTITUTE(O35,",","")),0) -> 2 | AE35: =IFERROR(VALUE(SUBSTITUTE(V35,",","")),0) -> 5189.28 | AF35: =IF(ISNUMBER(SEARCH("FOC",W35)),"FOC",IF(ISNUMBER(SEARCH("샘플",W35)),"Sample","Paid")) -> Paid
A36: 34 | B36: 06312 | C36: KR | D36: OPO | E36: 2026-06-16 | F36: minju | G36: MOARS | I36: Netherlands The | J36: KR-OVERSEAS | K36: ALSC01-Fgr | L36: (리뉴얼) 프레시 그린 라이스 모찌 클렌저 120G | M36: 아렌시아 | N36: USD | O36: 580 | P36: 6.24 | Q36: 3,619.20 | R36: 0.00 | S36: 5,332,891.20 | T36: 6,600.00 | U36: 3,828,000.00 | V36: 1,504,891.20 | X36: 28.2 | Y36: IN00444093 | AA36: =LEFT(E36,7) -> 2026-06 | AB36: =IF(AND($AA36>="2025-01",$AA36<="2025-06"),"H1_2025",IF(AND($AA36>="2026-01",$AA36<="2026-06"),"H1_2026","")) -> H1_2026 | AC36: =IFERROR(VALUE(SUBSTITUTE(S36,",","")),0) -> 5332891.2 | AD36: =IFERROR(VALUE(SUBSTITUTE(O36,",","")),0) -> 580 | AE36: =IFERROR(VALUE(SUBSTITUTE(V36,",","")),0) -> 1504891.2 | AF36: =IF(ISNUMBER(SEARCH("FOC",W36)),"FOC",IF(ISNUMBER(SEARCH("샘플",W36)),"Sample","Paid")) -> Paid
A37: 35 | B37: 06312 | C37: KR | D37: OPO | E37: 2026-06-16 | F37: minju | G37: MOARS | I37: Netherlands The | J37: KR-OVERSEAS | K37: ALSS11-SR | L37: 레틴알 부스터 샷 30ml | M37: 아렌시아 | N37: USD | O37: 610 | P37: 7.78 | Q37: 4,745.80 | R37: 0.00 | S37: 6,992,936.30 | T37: 7,000.00 | U37: 4,270,000.00 | V37: 2,722,936.30 | X37: 38.9 | Y37: IN00444093 | AA37: =LEFT(E37,7) -> 2026-06 | AB37: =IF(AND($AA37>="2025-01",$AA37<="2025-06"),"H1_2025",IF(AND($AA37>="2026-01",$AA37<="2026-06"),"H1_2026","")) -> H1_2026 | AC37: =IFERROR(VALUE(SUBSTITUTE(S37,",","")),0) -> 6992936.3 | AD37: =IFERROR(VALUE(SUBSTITUTE(O37,",","")),0) -> 610 | AE37: =IFERROR(VALUE(SUBSTITUTE(V37,",","")),0) -> 2722936.3 | AF37: =IF(ISNUMBER(SEARCH("FOC",W37)),"FOC",IF(ISNUMBER(SEARCH("샘플",W37)),"Sample","Paid")) -> Paid
A38: 36 | B38: 06312 | C38: KR | D38: OPO | E38: 2026-06-16 | F38: minju | G38: MOARS | I38: Netherlands The | J38: KR-OVERSEAS | K38: ALSS11-SV | L38: 비타민 C 부스터 샷 30ml | M38: 아렌시아 | N38: USD | O38: 2,600 | P38: 7.78 | Q38: 20,228.00 | R38: 0.00 | S38: 29,805,958.00 | T38: 8,000.00 | U38: 20,800,000.00 | V38: 9,005,958.00 | X38: 30.2 | Y38: IN00444093 | AA38: =LEFT(E38,7) -> 2026-06 | AB38: =IF(AND($AA38>="2025-01",$AA38<="2025-06"),"H1_2025",IF(AND($AA38>="2026-01",$AA38<="2026-06"),"H1_2026","")) -> H1_2026 | AC38: =IFERROR(VALUE(SUBSTITUTE(S38,",","")),0) -> 29805958 | AD38: =IFERROR(VALUE(SUBSTITUTE(O38,",","")),0) -> 2600 | AE38: =IFERROR(VALUE(SUBSTITUTE(V38,",","")),0) -> 9005958 | AF38: =IF(ISNUMBER(SEARCH("FOC",W38)),"FOC",IF(ISNUMBER(SEARCH("샘플",W38)),"Sample","Paid")) -> Paid
A39: 37 | B39: 06312 | C39: KR | D39: OPO | E39: 2026-06-16 | F39: minju | G39: MOARS | I39: Netherlands The | J39: KR-OVERSEAS | K39: ANC01-FQRRR | L39: [리뉴얼] 어성초 쿼세티놀 모공 딥 클렌징폼 150ml | M39: 아누아 | N39: USD | O39: 9,770 | P39: 5.99 | Q39: 58,522.30 | R39: 0.00 | S39: 86,232,609.05 | T39: 7,760.00 | U39: 75,815,200.00 | V39: 10,417,409.05 | X39: 12.1 | Y39: IN00444093 | AA39: =LEFT(E39,7) -> 2026-06 | AB39: =IF(AND($AA39>="2025-01",$AA39<="2025-06"),"H1_2025",IF(AND($AA39>="2026-01",$AA39<="2026-06"),"H1_2026","")) -> H1_2026 | AC39: =IFERROR(VALUE(SUBSTITUTE(S39,",","")),0) -> 86232609 | AD39: =IFERROR(VALUE(SUBSTITUTE(O39,",","")),0) -> 9770 | AE39: =IFERROR(VALUE(SUBSTITUTE(V39,",","")),0) -> 10417409 | AF39: =IF(ISNUMBER(SEARCH("FOC",W39)),"FOC",IF(ISNUMBER(SEARCH("샘플",W39)),"Sample","Paid")) -> Paid
A40: 38 | B40: 06312 | C40: KR | D40: OPO | E40: 2026-06-16 | F40: minju | G40: MOARS | I40: Netherlands The | J40: KR-OVERSEAS | K40: ANC01-FSR | L40: [리뉴얼] 어성초 석시닉 모이스처 클렌징폼 150ml | M40: 아누아 | N40: USD | O40: 290 | P40: 6.01 | Q40: 1,742.90 | R40: 0.00 | S40: 2,568,163.15 | T40: 7,760.00 | U40: 2,250,400.00 | V40: 317,763.15 | X40: 12.4 | Y40: IN00444093 | AA40: =LEFT(E40,7) -> 2026-06 | AB40: =IF(AND($AA40>="2025-01",$AA40<="2025-06"),"H1_2025",IF(AND($AA40>="2026-01",$AA40<="2026-06"),"H1_2026","")) -> H1_2026 | AC40: =IFERROR(VALUE(SUBSTITUTE(S40,",","")),0) -> 2568163.1 | AD40: =IFERROR(VALUE(SUBSTITUTE(O40,",","")),0) -> 290 | AE40: =IFERROR(VALUE(SUBSTITUTE(V40,",","")),0) -> 317763.15 | AF40: =IF(ISNUMBER(SEARCH("FOC",W40)),"FOC",IF(ISNUMBER(SEARCH("샘플",W40)),"Sample","Paid")) -> Paid
A41: 39 | B41: 06312 | C41: KR | D41: OPO | E41: 2026-06-16 | F41: minju | G41: MOARS | I41: Netherlands The | J41: KR-OVERSEAS | K41: ANC01-OCR | L41: [리뉴얼] 어성초 포어 컨트롤 클렌징 오일 200ml | M41: 아누아 | N41: USD | O41: 10,570 | P41: 8.51 | Q41: 89,950.70 | R41: 0.00 | S41: 132,542,356.45 | T41: 5,572.50 | U41: 58,901,280.00 | V41: 73,641,076.45 | X41: 55.6 | Y41: IN00444093 | AA41: =LEFT(E41,7) -> 2026-06 | AB41: =IF(AND($AA41>="2025-01",$AA41<="2025-06"),"H1_2025",IF(AND($AA41>="2026-01",$AA41<="2026-06"),"H1_2026","")) -> H1_2026 | AC41: =IFERROR(VALUE(SUBSTITUTE(S41,",","")),0) -> 1.3254236e+08 | AD41: =IFERROR(VALUE(SUBSTITUTE(O41,",","")),0) -> 10570 | AE41: =IFERROR(VALUE(SUBSTITUTE(V41,",","")),0) -> 73641076 | AF41: =IF(ISNUMBER(SEARCH("FOC",W41)),"FOC",IF(ISNUMBER(SEARCH("샘플",W41)),"Sample","Paid")) -> Paid
...

Sheet H1 Analysis
A1: MOARS — H1 Sales Review & Comparison: 2025 vs 2026
A2: Client: MOARS (ships to Netherlands) · Currency: KRW (converted amount / 환산금액) · Period: Jan–Jun · Purpose: H1 retrospective & H2 insight · Source: {worksheet}
A4: KEY METRICS
A5: Metric | B5: H1 2025 | C5: H1 2026 | D5: Δ | E5: YoY %
A6: Total Revenue (KRW) | B6: =SUMIFS('{worksheet}'!$AC$3:$AC$4127,'{worksheet}'!$AB$3:$AB$4127,"H1_2025") -> 4.5228118e+09 | C6: =SUMIFS('{worksheet}'!$AC$3:$AC$4127,'{worksheet}'!$AB$3:$AB$4127,"H1_2026") -> 8.1526898e+09 | D6: =C6-B6 -> 3.629878e+09 | E6: =IF(B6=0,"",C6/B6-1) -> 0.80257109
A7: Gross Profit (KRW) | B7: =SUMIFS('{worksheet}'!$AE$3:$AE$4127,'{worksheet}'!$AB$3:$AB$4127,"H1_2025") -> 9.0410372e+08 | C7: =SUMIFS('{worksheet}'!$AE$3:$AE$4127,'{worksheet}'!$AB$3:$AB$4127,"H1_2026") -> 1.8934963e+09 | D7: =C7-B7 -> 9.8939253e+08 | E7: =IF(B7=0,"",C7/B7-1) -> 1.0943352
A8: Gross Margin % | B8: =IF(B6=0,"",B7/B6) -> 0.19989859 | C8: =IF(C6=0,"",C7/C6) -> 0.23225418 | D8: =IF(OR(B8="",C8=""),"",C8-B8) -> 0.032355582
A9: Units Sold | B9: =SUMIFS('{worksheet}'!$AD$3:$AD$4127,'{worksheet}'!$AB$3:$AB$4127,"H1_2025") -> 939458 | C9: =SUMIFS('{worksheet}'!$AD$3:$AD$4127,'{worksheet}'!$AB$3:$AB$4127,"H1_2026") -> 807407 | D9: =C9-B9 -> -132051 | E9: =IF(B9=0,"",C9/B9-1) -> -0.14056083
A10: Transactions (line items) | B10: =COUNTIFS('{worksheet}'!$AB$3:$AB$4127,"H1_2025") -> 949 | C10: =COUNTIFS('{worksheet}'!$AB$3:$AB$4127,"H1_2026") -> 1566 | D10: =C10-B10 -> 617 | E10: =IF(B10=0,"",C10/B10-1) -> 0.65015806
A11: Active Brands (rev > 0) | B11: =COUNTIF($D$26:$D$117,">0") -> 59 | C11: =COUNTIF($E$26:$E$117,">0") -> 63 | D11: =C11-B11 -> 4
A12: Free Units (Sample + FOC) | B12: =SUMIFS('{worksheet}'!$AD$3:$AD$4127,'{worksheet}'!$AB$3:$AB$4127,"H1_2025",'{worksheet}'!$AF$3:$AF$4127,"Sample")+SUMIFS('{worksheet}'!$AD$3:$AD$4127,'{worksheet}'!$AB$3:$AB$4127,"H1_2025",'{worksheet}'!$AF$3:$AF$4127,"FOC") -> 36542 | C12: =SUMIFS('{worksheet}'!$AD$3:$AD$4127,'{worksheet}'!$AB$3:$AB$4127,"H1_2026",'{worksheet}'!$AF$3:$AF$4127,"Sample")+SUMIFS('{worksheet}'!$AD$3:$AD$4127,'{worksheet}'!$AB$3:$AB$4127,"H1_2026",'{worksheet}'!$AF$3:$AF$4127,"FOC") -> 7223 | D12: =C12-B12 -> -29319 | E12: =IF(B12=0,"",C12/B12-1) -> -0.80233704
A14: MONTHLY REVENUE TREND (KRW)
A15: Month | B15: 2025 | C15: 2026 | D15: YoY %
A16: Jan | B16: =SUMIFS('{worksheet}'!$AC$3:$AC$4127,'{worksheet}'!$AA$3:$AA$4127,"2025-"&TEXT(ROW()-15,"00")) -> 94130266 | C16: =SUMIFS('{worksheet}'!$AC$3:$AC$4127,'{worksheet}'!$AA$3:$AA$4127,"2026-"&TEXT(ROW()-15,"00")) -> 4.5555454e+08 | D16: =IF(B16=0,"",C16/B16-1) -> 3.8396181
A17: Feb | B17: =SUMIFS('{worksheet}'!$AC$3:$AC$4127,'{worksheet}'!$AA$3:$AA$4127,"2025-"&TEXT(ROW()-15,"00")) -> 5.6477425e+08 | C17: =SUMIFS('{worksheet}'!$AC$3:$AC$4127,'{worksheet}'!$AA$3:$AA$4127,"2026-"&TEXT(ROW()-15,"00")) -> 1.1587206e+09 | D17: =IF(B17=0,"",C17/B17-1) -> 1.0516527
A18: Mar | B18: =SUMIFS('{worksheet}'!$AC$3:$AC$4127,'{worksheet}'!$AA$3:$AA$4127,"2025-"&TEXT(ROW()-15,"00")) -> 1.058785e+09 | C18: =SUMIFS('{worksheet}'!$AC$3:$AC$4127,'{worksheet}'!$AA$3:$AA$4127,"2026-"&TEXT(ROW()-15,"00")) -> 1.9159751e+09 | D18: =IF(B18=0,"",C18/B18-1) -> 0.80959782
A19: Apr | B19: =SUMIFS('{worksheet}'!$AC$3:$AC$4127,'{worksheet}'!$AA$3:$AA$4127,"2025-"&TEXT(ROW()-15,"00")) -> 1.0903516e+09 | C19: =SUMIFS('{worksheet}'!$AC$3:$AC$4127,'{worksheet}'!$AA$3:$AA$4127,"2026-"&TEXT(ROW()-15,"00")) -> 8.8905312e+08 | D19: =IF(B19=0,"",C19/B19-1) -> -0.18461793
A20: May | B20: =SUMIFS('{worksheet}'!$AC$3:$AC$4127,'{worksheet}'!$AA$3:$AA$4127,"2025-"&TEXT(ROW()-15,"00")) -> 8.8225913e+08 | C20: =SUMIFS('{worksheet}'!$AC$3:$AC$4127,'{worksheet}'!$AA$3:$AA$4127,"2026-"&TEXT(ROW()-15,"00")) -> 1.284503e+09 | D20: =IF(B20=0,"",C20/B20-1) -> 0.45592487
A21: Jun | B21: =SUMIFS('{worksheet}'!$AC$3:$AC$4127,'{worksheet}'!$AA$3:$AA$4127,"2025-"&TEXT(ROW()-15,"00")) -> 8.3251153e+08 | C21: =SUMIFS('{worksheet}'!$AC$3:$AC$4127,'{worksheet}'!$AA$3:$AA$4127,"2026-"&TEXT(ROW()-15,"00")) -> 2.4488834e+09 | D21: =IF(B21=0,"",C21/B21-1) -> 1.941561
A22: H1 Total | B22: =SUM(B16:B21) -> 4.5228118e+09 | C22: =SUM(C16:C21) -> 8.1526898e+09 | D22: =IF(B22=0,"",C22/B22-1) -> 0.80257109
A24: BRAND COMPARISON — H1 2025 vs H1 2026 (Revenue in KRW, sorted by H1'26 revenue)
A25: # | B25: Brand (EN) | C25: Brand (source) | D25: Rev H1'25 | E25: Rev H1'26 | F25: Δ Rev | G25: YoY % | H25: Units'25 | I25: Units'26 | J25: Profit'26 | K25: Margin'26 | L25: Free units'26 | M25: Status
A26: 1 | B26: Beauty of Joseon | C26: 조선미녀 | D26: =SUMIFS('{worksheet}'!$AC$3:$AC$4127,'{worksheet}'!$AB$3:$AB$4127,"H1_2025",'{worksheet}'!$M$3:$M$4127,$C26) -> 2.1048138e+09 | E26: =SUMIFS('{worksheet}'!$AC$3:$AC$4127,'{worksheet}'!$AB$3:$AB$4127,"H1_2026",'{worksheet}'!$M$3:$M$4127,$C26) -> 2.2701934e+09 | F26: =E26-D26 -> 1.6537959e+08 | G26: =IF(D26=0,"",E26/D26-1) -> 0.078572079 | H26: =SUMIFS('{worksheet}'!$AD$3:$AD$4127,'{worksheet}'!$AB$3:$AB$4127,"H1_2025",'{worksheet}'!$M$3:$M$4127,$C26) -> 225916 | I26: =SUMIFS('{worksheet}'!$AD$3:$AD$4127,'{worksheet}'!$AB$3:$AB$4127,"H1_2026",'{worksheet}'!$M$3:$M$4127,$C26) -> 233800 | J26: =SUMIFS('{worksheet}'!$AE$3:$AE$4127,'{worksheet}'!$AB$3:$AB$4127,"H1_2026",'{worksheet}'!$M$3:$M$4127,$C26) -> 4.8589813e+08 | K26: =IF(E26=0,"",J26/E26) -> 0.21403381 | L26: =SUMIFS('{worksheet}'!$AD$3:$AD$4127,'{worksheet}'!$AB$3:$AB$4127,"H1_2026",'{worksheet}'!$M$3:$M$4127,$C26,'{worksheet}'!$AF$3:$AF$4127,"Sample")+SUMIFS('{worksheet}'!$AD$3:$AD$4127,'{worksheet}'!$AB$3:$AB$4127,"H1_2026",'{worksheet}'!$M$3:$M$4127,$C26,'{worksheet}'!$AF$3:$AF$4127,"FOC") -> 0 | M26: =IF(AND(D26=0,E26>0),"New in H1'26",IF(AND(D26>0,E26=0),"Exited",IF(G26="","",IF(G26>=0.2,"Growth",IF(G26<=-0.2,"Decline","Stable"))))) -> Stable
A27: 2 | B27: medicube | C27: 메디큐브 | D27: =SUMIFS('{worksheet}'!$AC$3:$AC$4127,'{worksheet}'!$AB$3:$AB$4127,"H1_2025",'{worksheet}'!$M$3:$M$4127,$C27) -> 3.9262294e+08 | E27: =SUMIFS('{worksheet}'!$AC$3:$AC$4127,'{worksheet}'!$AB$3:$AB$4127,"H1_2026",'{worksheet}'!$M$3:$M$4127,$C27) -> 1.9810588e+09 | F27: =E27-D27 -> 1.5884358e+09 | G27: =IF(D27=0,"",E27/D27-1) -> 4.0457031 | H27: =SUMIFS('{worksheet}'!$AD$3:$AD$4127,'{worksheet}'!$AB$3:$AB$4127,"H1_2025",'{worksheet}'!$M$3:$M$4127,$C27) -> 25040 | I27: =SUMIFS('{worksheet}'!$AD$3:$AD$4127,'{worksheet}'!$AB$3:$AB$4127,"H1_2026",'{worksheet}'!$M$3:$M$4127,$C27) -> 136613 | J27: =SUMIFS('{worksheet}'!$AE$3:$AE$4127,'{worksheet}'!$AB$3:$AB$4127,"H1_2026",'{worksheet}'!$M$3:$M$4127,$C27) -> 4.2827852e+08 | K27: =IF(E27=0,"",J27/E27) -> 0.21618668 | L27: =SUMIFS('{worksheet}'!$AD$3:$AD$4127,'{worksheet}'!$AB$3:$AB$4127,"H1_2026",'{worksheet}'!$M$3:$M$4127,$C27,'{worksheet}'!$AF$3:$AF$4127,"Sample")+SUMIFS('{worksheet}'!$AD$3:$AD$4127,'{worksheet}'!$AB$3:$AB$4127,"H1_2026",'{worksheet}'!$M$3:$M$4127,$C27,'{worksheet}'!$AF$3:$AF$4127,"FOC") -> 0 | M27: =IF(AND(D27=0,E27>0),"New in H1'26",IF(AND(D27>0,E27=0),"Exited",IF(G27="","",IF(G27>=0.2,"Growth",IF(G27<=-0.2,"Decline","Stable"))))) -> Growth
A28: 3 | B28: Anua | C28: 아누아 | D28: =SUMIFS('{worksheet}'!$AC$3:$AC$4127,'{worksheet}'!$AB$3:$AB$4127,"H1_2025",'{worksheet}'!$M$3:$M$4127,$C28) -> 20961 | E28: =SUMIFS('{worksheet}'!$AC$3:$AC$4127,'{worksheet}'!$AB$3:$AB$4127,"H1_2026",'{worksheet}'!$M$3:$M$4127,$C28) -> 1.4155911e+09 | F28: =E28-D28 -> 1.4155701e+09 | G28: =IF(D28=0,"",E28/D28-1) -> 67533.521 | H28: =SUMIFS('{worksheet}'!$AD$3:$AD$4127,'{worksheet}'!$AB$3:$AB$4127,"H1_2025",'{worksheet}'!$M$3:$M$4127,$C28) -> 1513 | I28: =SUMIFS('{worksheet}'!$AD$3:$AD$4127,'{worksheet}'!$AB$3:$AB$4127,"H1_2026",'{worksheet}'!$M$3:$M$4127,$C28) -> 121374 | J28: =SUMIFS('{worksheet}'!$AE$3:$AE$4127,'{worksheet}'!$AB$3:$AB$4127,"H1_2026",'{worksheet}'!$M$3:$M$4127,$C28) -> 2.8123517e+08 | K28: =IF(E28=0,"",J28/E28) -> 0.19866978 | L28: =SUMIFS('{worksheet}'!$AD$3:$AD$4127,'{worksheet}'!$AB$3:$AB$4127,"H1_2026",'{worksheet}'!$M$3:$M$4127,$C28,'{worksheet}'!$AF$3:$AF$4127,"Sample")+SUMIFS('{worksheet}'!$AD$3:$AD$4127,'{worksheet}'!$AB$3:$AB$4127,"H1_2026",'{worksheet}'!$M$3:$M$4127,$C28,'{worksheet}'!$AF$3:$AF$4127,"FOC") -> 0 | M28: =IF(AND(D28=0,E28>0),"New in H1'26",IF(AND(D28>0,E28=0),"Exited",IF(G28="","",IF(G28>=0.2,"Growth",IF(G28<=-0.2,"Decline","Stable"))))) -> Growth
A29: 4 | B29: COSRX | C29: 코스알엑스 | D29: =SUMIFS('{worksheet}'!$AC$3:$AC$4127,'{worksheet}'!$AB$3:$AB$4127,"H1_2025",'{worksheet}'!$M$3:$M$4127,$C29) -> 97689804 | E29: =SUMIFS('{worksheet}'!$AC$3:$AC$4127,'{worksheet}'!$AB$3:$AB$4127,"H1_2026",'{worksheet}'!$M$3:$M$4127,$C29) -> 4.3602826e+08 | F29: =E29-D29 -> 3.3833846e+08 | G29: =IF(D29=0,"",E29/D29-1) -> 3.4633958 | H29: =SUMIFS('{worksheet}'!$AD$3:$AD$4127,'{worksheet}'!$AB$3:$AB$4127,"H1_2025",'{worksheet}'!$M$3:$M$4127,$C29) -> 14537 | I29: =SUMIFS('{worksheet}'!$AD$3:$AD$4127,'{worksheet}'!$AB$3:$AB$4127,"H1_2026",'{worksheet}'!$M$3:$M$4127,$C29) -> 50859 | J29: =SUMIFS('{worksheet}'!$AE$3:$AE$4127,'{worksheet}'!$AB$3:$AB$4127,"H1_2026",'{worksheet}'!$M$3:$M$4127,$C29) -> 1.1373443e+08 | K29: =IF(E29=0,"",J29/E29) -> 0.26084187 | L29: =SUMIFS('{worksheet}'!$AD$3:$AD$4127,'{worksheet}'!$AB$3:$AB$4127,"H1_2026",'{worksheet}'!$M$3:$M$4127,$C29,'{worksheet}'!$AF$3:$AF$4127,"Sample")+SUMIFS('{worksheet}'!$AD$3:$AD$4127,'{worksheet}'!$AB$3:$AB$4127,"H1_2026",'{worksheet}'!$M$3:$M$4127,$C29,'{worksheet}'!$AF$3:$AF$4127,"FOC") -> 0 | M29: =IF(AND(D29=0,E29>0),"New in H1'26",IF(AND(D29>0,E29=0),"Exited",IF(G29="","",IF(G29>=0.2,"Growth",IF(G29<=-0.2,"Decline","Stable"))))) -> Growth
A30: 5 | B30: Round Lab | C30: 라운드랩 | D30: =SUMIFS('{worksheet}'!$AC$3:$AC$4127,'{worksheet}'!$AB$3:$AB$4127,"H1_2025",'{worksheet}'!$M$3:$M$4127,$C30) -> 48847212 | E30: =SUMIFS('{worksheet}'!$AC$3:$AC$4127,'{worksheet}'!$AB$3:$AB$4127,"H1_2026",'{worksheet}'!$M$3:$M$4127,$C30) -> 3.1603714e+08 | F30: =E30-D30 -> 2.6718993e+08 | G30: =IF(D30=0,"",E30/D30-1) -> 5.4699114 | H30: =SUMIFS('{worksheet}'!$AD$3:$AD$4127,'{worksheet}'!$AB$3:$AB$4127,"H1_2025",'{worksheet}'!$M$3:$M$4127,$C30) -> 15098 | I30: =SUMIFS('{worksheet}'!$AD$3:$AD$4127,'{worksheet}'!$AB$3:$AB$4127,"H1_2026",'{worksheet}'!$M$3:$M$4127,$C30) -> 42384 | J30: =SUMIFS('{worksheet}'!$AE$3:$AE$4127,'{worksheet}'!$AB$3:$AB$4127,"H1_2026",'{worksheet}'!$M$3:$M$4127,$C30) -> 76256088 | K30: =IF(E30=0,"",J30/E30) -> 0.24128838 | L30: =SUMIFS('{worksheet}'!$AD$3:$AD$4127,'{worksheet}'!$AB$3:$AB$4127,"H1_2026",'{worksheet}'!$M$3:$M$4127,$C30,'{worksheet}'!$AF$3:$AF$4127,"Sample")+SUMIFS('{worksheet}'!$AD$3:$AD$4127,'{worksheet}'!$AB$3:$AB$4127,"H1_2026",'{worksheet}'!$M$3:$M$4127,$C30,'{worksheet}'!$AF$3:$AF$4127,"FOC") -> 0 | M30: =IF(AND(D30=0,E30>0),"New in H1'26",IF(AND(D30>0,E30=0),"Exited",IF(G30="","",IF(G30>=0.2,"Growth",IF(G30<=-0.2,"Decline","Stable"))))) -> Growth
A31: 6 | B31: Celimax | C31: 셀리맥스 | D31: =SUMIFS('{worksheet}'!$AC$3:$AC$4127,'{worksheet}'!$AB$3:$AB$4127,"H1_2025",'{worksheet}'!$M$3:$M$4127,$C31) -> 74354178 | E31: =SUMIFS('{worksheet}'!$AC$3:$AC$4127,'{worksheet}'!$AB$3:$AB$4127,"H1_2026",'{worksheet}'!$M$3:$M$4127,$C31) -> 2.8216878e+08 | F31: =E31-D31 -> 2.0781461e+08 | G31: =IF(D31=0,"",E31/D31-1) -> 2.7949284 | H31: =SUMIFS('{worksheet}'!$AD$3:$AD$4127,'{worksheet}'!$AB$3:$AB$4127,"H1_2025",'{worksheet}'!$M$3:$M$4127,$C31) -> 8842 | I31: =SUMIFS('{worksheet}'!$AD$3:$AD$4127,'{worksheet}'!$AB$3:$AB$4127,"H1_2026",'{worksheet}'!$M$3:$M$4127,$C31) -> 29064 | J31: =SUMIFS('{worksheet}'!$AE$3:$AE$4127,'{worksheet}'!$AB$3:$AB$4127,"H1_2026",'{worksheet}'!$M$3:$M$4127,$C31) -> 97800169 | K31: =IF(E31=0,"",J31/E31) -> 0.34660166 | L31: =SUMIFS('{worksheet}'!$AD$3:$AD$4127,'{worksheet}'!$AB$3:$AB$4127,"H1_2026",'{worksheet}'!$M$3:$M$4127,$C31,'{worksheet}'!$AF$3:$AF$4127,"Sample")+SUMIFS('{worksheet}'!$AD$3:$AD$4127,'{worksheet}'!$AB$3:$AB$4127,"H1_2026",'{worksheet}'!$M$3:$M$4127,$C31,'{worksheet}'!$AF$3:$AF$4127,"FOC") -> 0 | M31: =IF(AND(D31=0,E31>0),"New in H1'26",IF(AND(D31>0,E31=0),"Exited",IF(G31="","",IF(G31>=0.2,"Growth",IF(G31<=-0.2,"Decline","Stable"))))) -> Growth
A32: 7 | B32: Pyunkang Yul | C32: 편강율 | D32: =SUMIFS('{worksheet}'!$AC$3:$AC$4127,'{worksheet}'!$AB$3:$AB$4127,"H1_2025",'{worksheet}'!$M$3:$M$4127,$C32) -> 2.7657695e+08 | E32: =SUMIFS('{worksheet}'!$AC$3:$AC$4127,'{worksheet}'!$AB$3:$AB$4127,"H1_2026",'{worksheet}'!$M$3:$M$4127,$C32) -> 2.7213084e+08 | F32: =E32-D32 -> -4446108.3 | G32: =IF(D32=0,"",E32/D32-1) -> -0.016075484 | H32: =SUMIFS('{worksheet}'!$AD$3:$AD$4127,'{worksheet}'!$AB$3:$AB$4127,"H1_2025",'{worksheet}'!$M$3:$M$4127,$C32) -> 178311 | I32: =SUMIFS('{worksheet}'!$AD$3:$AD$4127,'{worksheet}'!$AB$3:$AB$4127,"H1_2026",'{worksheet}'!$M$3:$M$4127,$C32) -> 38318 | J32: =SUMIFS('{worksheet}'!$AE$3:$AE$4127,'{worksheet}'!$AB$3:$AB$4127,"H1_2026",'{worksheet}'!$M$3:$M$4127,$C32) -> 52983862 | K32: =IF(E32=0,"",J32/E32) -> 0.19469996 | L32: =SUMIFS('{worksheet}'!$AD$3:$AD$4127,'{worksheet}'!$AB$3:$AB$4127,"H1_2026",'{worksheet}'!$M$3:$M$4127,$C32,'{worksheet}'!$AF$3:$AF$4127,"Sample")+SUMIFS('{worksheet}'!$AD$3:$AD$4127,'{worksheet}'!$AB$3:$AB$4127,"H1_2026",'{worksheet}'!$M$3:$M$4127,$C32,'{worksheet}'!$AF$3:$AF$4127,"FOC") -> 3750 | M32: =IF(AND(D32=0,E32>0),"New in H1'26",IF(AND(D32>0,E32=0),"Exited",IF(G32="","",IF(G32>=0.2,"Growth",IF(G32<=-0.2,"Decline","Stable"))))) -> Stable
A33: 8 | B33: BIODANCE | C33: 바이오던스 | D33: =SUMIFS('{worksheet}'!$AC$3:$AC$4127,'{worksheet}'!$AB$3:$AB$4127,"H1_2025",'{worksheet}'!$M$3:$M$4127,$C33) -> 63799921 | E33: =SUMIFS('{worksheet}'!$AC$3:$AC$4127,'{worksheet}'!$AB$3:$AB$4127,"H1_2026",'{worksheet}'!$M$3:$M$4127,$C33) -> 2.5165444e+08 | F33: =E33-D33 -> 1.8785452e+08 | G33: =IF(D33=0,"",E33/D33-1) -> 2.9444318 | H33: =SUMIFS('{worksheet}'!$AD$3:$AD$4127,'{worksheet}'!$AB$3:$AB$4127,"H1_2025",'{worksheet}'!$M$3:$M$4127,$C33) -> 5558 | I33: =SUMIFS('{worksheet}'!$AD$3:$AD$4127,'{worksheet}'!$AB$3:$AB$4127,"H1_2026",'{worksheet}'!$M$3:$M$4127,$C33) -> 21824 | J33: =SUMIFS('{worksheet}'!$AE$3:$AE$4127,'{worksheet}'!$AB$3:$AB$4127,"H1_2026",'{worksheet}'!$M$3:$M$4127,$C33) -> 1.1303176e+08 | K33: =IF(E33=0,"",J33/E33) -> 0.44915464 | L33: =SUMIFS('{worksheet}'!$AD$3:$AD$4127,'{worksheet}'!$AB$3:$AB$4127,"H1_2026",'{worksheet}'!$M$3:$M$4127,$C33,'{worksheet}'!$AF$3:$AF$4127,"Sample")+SUMIFS('{worksheet}'!$AD$3:$AD$4127,'{worksheet}'!$AB$3:$AB$4127,"H1_2026",'{worksheet}'!$M$3:$M$4127,$C33,'{worksheet}'!$AF$3:$AF$4127,"FOC") -> 0 | M33: =IF(AND(D33=0,E33>0),"New in H1'26",IF(AND(D33>0,E33=0),"Exited",IF(G33="","",IF(G33>=0.2,"Growth",IF(G33<=-0.2,"Decline","Stable"))))) -> Growth
A34: 9 | B34: Arencia | C34: 아렌시아 | D34: =SUMIFS('{worksheet}'!$AC$3:$AC$4127,'{worksheet}'!$AB$3:$AB$4127,"H1_2025",'{worksheet}'!$M$3:$M$4127,$C34) -> 0 | E34: =SUMIFS('{worksheet}'!$AC$3:$AC$4127,'{worksheet}'!$AB$3:$AB$4127,"H1_2026",'{worksheet}'!$M$3:$M$4127,$C34) -> 1.5960145e+08 | F34: =E34-D34 -> 1.5960145e+08 | G34: =IF(D34=0,"",E34/D34-1) | H34: =SUMIFS('{worksheet}'!$AD$3:$AD$4127,'{worksheet}'!$AB$3:$AB$4127,"H1_2025",'{worksheet}'!$M$3:$M$4127,$C34) -> 0 | I34: =SUMIFS('{worksheet}'!$AD$3:$AD$4127,'{worksheet}'!$AB$3:$AB$4127,"H1_2026",'{worksheet}'!$M$3:$M$4127,$C34) -> 14702 | J34: =SUMIFS('{worksheet}'!$AE$3:$AE$4127,'{worksheet}'!$AB$3:$AB$4127,"H1_2026",'{worksheet}'!$M$3:$M$4127,$C34) -> 53993666 | K34: =IF(E34=0,"",J34/E34) -> 0.3383031 | L34: =SUMIFS('{worksheet}'!$AD$3:$AD$4127,'{worksheet}'!$AB$3:$AB$4127,"H1_2026",'{worksheet}'!$M$3:$M$4127,$C34,'{worksheet}'!$AF$3:$AF$4127,"Sample")+SUMIFS('{worksheet}'!$AD$3:$AD$4127,'{worksheet}'!$AB$3:$AB$4127,"H1_2026",'{worksheet}'!$M$3:$M$4127,$C34,'{worksheet}'!$AF$3:$AF$4127,"FOC") -> 0 | M34: =IF(AND(D34=0,E34>0),"New in H1'26",IF(AND(D34>0,E34=0),"Exited",IF(G34="","",IF(G34>=0.2,"Growth",IF(G34<=-0.2,"Decline","Stable"))))) -> New in H1'26
A35: 10 | B35: Dr.Rejuol | C35: 닥터 리쥬올 | D35: =SUMIFS('{worksheet}'!$AC$3:$AC$4127,'{worksheet}'!$AB$3:$AB$4127,"H1_2025",'{worksheet}'!$M$3:$M$4127,$C35) -> 0 | E35: =SUMIFS('{worksheet}'!$AC$3:$AC$4127,'{worksheet}'!$AB$3:$AB$4127,"H1_2026",'{worksheet}'!$M$3:$M$4127,$C35) -> 1.3667044e+08 | F35: =E35-D35 -> 1.3667044e+08 | G35: =IF(D35=0,"",E35/D35-1) | H35: =SUMIFS('{worksheet}'!$AD$3:$AD$4127,'{worksheet}'!$AB$3:$AB$4127,"H1_2025",'{worksheet}'!$M$3:$M$4127,$C35) -> 0 | I35: =SUMIFS('{worksheet}'!$AD$3:$AD$4127,'{worksheet}'!$AB$3:$AB$4127,"H1_2026",'{worksheet}'!$M$3:$M$4127,$C35) -> 5628 | J35: =SUMIFS('{worksheet}'!$AE$3:$AE$4127,'{worksheet}'!$AB$3:$AB$4127,"H1_2026",'{worksheet}'!$M$3:$M$4127,$C35) -> 43924343 | K35: =IF(E35=0,"",J35/E35) -> 0.32138875 | L35: =SUMIFS('{worksheet}'!$AD$3:$AD$4127,'{worksheet}'!$AB$3:$AB$4127,"H1_2026",'{worksheet}'!$M$3:$M$4127,$C35,'{worksheet}'!$AF$3:$AF$4127,"Sample")+SUMIFS('{worksheet}'!$AD$3:$AD$4127,'{worksheet}'!$AB$3:$AB$4127,"H1_2026",'{worksheet}'!$M$3:$M$4127,$C35,'{worksheet}'!$AF$3:$AF$4127,"FOC") -> 588 | M35: =IF(AND(D35=0,E35>0),"New in H1'26",IF(AND(D35>0,E35=0),"Exited",IF(G35="","",IF(G35>=0.2,"Growth",IF(G35<=-0.2,"Decline","Stable"))))) -> New in H1'26
A36: 11 | B36: Heimish | C36: 헤이미쉬 | D36: =SUMIFS('{worksheet}'!$AC$3:$AC$4127,'{worksheet}'!$AB$3:$AB$4127,"H1_2025",'{worksheet}'!$M$3:$M$4127,$C36) -> 66711998 | E36: =SUMIFS('{worksheet}'!$AC$3:$AC$4127,'{worksheet}'!$AB$3:$AB$4127,"H1_2026",'{worksheet}'!$M$3:$M$4127,$C36) -> 80111800 | F36: =E36-D36 -> 13399802 | G36: =IF(D36=0,"",E36/D36-1) -> 0.20086045 | H36: =SUMIFS('{worksheet}'!$AD$3:$AD$4127,'{worksheet}'!$AB$3:$AB$4127,"H1_2025",'{worksheet}'!$M$3:$M$4127,$C36) -> 18708 | I36: =SUMIFS('{worksheet}'!$AD$3:$AD$4127,'{worksheet}'!$AB$3:$AB$4127,"H1_2026",'{worksheet}'!$M$3:$M$4127,$C36) -> 10915 | J36: =SUMIFS('{worksheet}'!$AE$3:$AE$4127,'{worksheet}'!$AB$3:$AB$4127,"H1_2026",'{worksheet}'!$M$3:$M$4127,$C36) -> 20259208 | K36: =IF(E36=0,"",J36/E36) -> 0.25288669 | L36: =SUMIFS('{worksheet}'!$AD$3:$AD$4127,'{worksheet}'!$AB$3:$AB$4127,"H1_2026",'{worksheet}'!$M$3:$M$4127,$C36,'{worksheet}'!$AF$3:$AF$4127,"Sample")+SUMIFS('{worksheet}'!$AD$3:$AD$4127,'{worksheet}'!$AB$3:$AB$4127,"H1_2026",'{worksheet}'!$M$3:$M$4127,$C36,'{worksheet}'!$AF$3:$AF$4127,"FOC") -> 0 | M36: =IF(AND(D36=0,E36>0),"New in H1'26",IF(AND(D36>0,E36=0),"Exited",IF(G36="","",IF(G36>=0.2,"Growth",IF(G36<=-0.2,"Decline","Stable"))))) -> Growth
A37: 12 | B37: Dr.Elsia | C37: 닥터엘시아 | D37: =SUMIFS('{worksheet}'!$AC$3:$AC$4127,'{worksheet}'!$AB$3:$AB$4127,"H1_2025",'{worksheet}'!$M$3:$M$4127,$C37) -> 7.5612225e+08 | E37: =SUMIFS('{worksheet}'!$AC$3:$AC$4127,'{worksheet}'!$AB$3:$AB$4127,"H1_2026",'{worksheet}'!$M$3:$M$4127,$C37) -> 76675686 | F37: =E37-D37 -> -6.7944656e+08 | G37: =IF(D37=0,"",E37/D37-1) -> -0.89859353 | H37: =SUMIFS('{worksheet}'!$AD$3:$AD$4127,'{worksheet}'!$AB$3:$AB$4127,"H1_2025",'{worksheet}'!$M$3:$M$4127,$C37) -> 57560 | I37: =SUMIFS('{worksheet}'!$AD$3:$AD$4127,'{worksheet}'!$AB$3:$AB$4127,"H1_2026",'{worksheet}'!$M$3:$M$4127,$C37) -> 6000 | J37: =SUMIFS('{worksheet}'!$AE$3:$AE$4127,'{worksheet}'!$AB$3:$AB$4127,"H1_2026",'{worksheet}'!$M$3:$M$4127,$C37) -> 18429186 | K37: =IF(E37=0,"",J37/E37) -> 0.24035241 | L37: =SUMIFS('{worksheet}'!$AD$3:$AD$4127,'{worksheet}'!$AB$3:$AB$4127,"H1_2026",'{worksheet}'!$M$3:$M$4127,$C37,'{worksheet}'!$AF$3:$AF$4127,"Sample")+SUMIFS('{worksheet}'!$AD$3:$AD$4127,'{worksheet}'!$AB$3:$AB$4127,"H1_2026",'{worksheet}'!$M$3:$M$4127,$C37,'{worksheet}'!$AF$3:$AF$4127,"FOC") -> 0 | M37: =IF(AND(D37=0,E37>0),"New in H1'26",IF(AND(D37>0,E37=0),"Exited",IF(G37="","",IF(G37>=0.2,"Growth",IF(G37<=-0.2,"Decline","Stable"))))) -> Decline
... A117: 92 | B117: Dr.Suracle | C117: 닥터슈라클 | D117: =SUMIFS('{worksheet}'!$AC$3:$AC$4127,'{worksheet}'!$AB$3:$AB$4127,"H1_2025",'{worksheet}'!$M$3:$M$4127,$C117) -> 0 | E117: =SUMIFS('{worksheet}'!$AC$3:$AC$4127,'{worksheet}'!$AB$3:$AB$4127,"H1_2026",'{worksheet}'!$M$3:$M$4127,$C117) -> 0 | F117: =E117-D117 -> 0 | G117: =IF(D117=0,"",E117/D117-1) | H117: =SUMIFS('{worksheet}'!$AD$3:$AD$4127,'{worksheet}'!$AB$3:$AB$4127,"H1_2025",'{worksheet}'!$M$3:$M$4127,$C117) -> 12 | I117: =SUMIFS('{worksheet}'!$AD$3:$AD$4127,'{worksheet}'!$AB$3:$AB$4127,"H1_2026",'{worksheet}'!$M$3:$M$4127,$C117) -> 0 | J117: =SUMIFS('{worksheet}'!$AE$3:$AE$4127,'{worksheet}'!$AB$3:$AB$4127,"H1_2026",'{worksheet}'!$M$3:$M$4127,$C117) -> 0 | K117: =IF(E117=0,"",J117/E117) | L117: =SUMIFS('{worksheet}'!$AD$3:$AD$4127,'{worksheet}'!$AB$3:$AB$4127,"H1_2026",'{worksheet}'!$M$3:$M$4127,$C117,'{worksheet}'!$AF$3:$AF$4127,"Sample")+SUMIFS('{worksheet}'!$AD$3:$AD$4127,'{worksheet}'!$AB$3:$AB$4127,"H1_2026",'{worksheet}'!$M$3:$M$4127,$C117,'{worksheet}'!$AF$3:$AF$4127,"FOC") -> 0 | M117: =IF(AND(D117=0,E117>0),"New in H1'26",IF(AND(D117>0,E117=0),"Exited",IF(G117="","",IF(G117>=0.2,"Growth",IF(G117<=-0.2,"Decline","Stable")))))
A120: [Chart data — Top 10 brands] | E120: [Chart data — Biggest movers by Δ Revenue]
A121: Brand | B121: H1 2025 | C121: H1 2026 | E121: Brand | F121: Δ Revenue
A122: =B26 -> Beauty of Joseon | B122: =D26 -> 2.1048138e+09 | C122: =E26 -> 2.2701934e+09 | E122: =INDEX($B$26:$B$117,MATCH(LARGE($F$26:$F$117,ROW()-121),$F$26:$F$117,0)) -> medicube | F122: =LARGE($F$26:$F$117,ROW()-121) -> 1.5884358e+09
A123: =B27 -> medicube | B123: =D27 -> 3.9262294e+08 | C123: =E27 -> 1.9810588e+09 | E123: =INDEX($B$26:$B$117,MATCH(LARGE($F$26:$F$117,ROW()-121),$F$26:$F$117,0)) -> Anua | F123: =LARGE($F$26:$F$117,ROW()-121) -> 1.4155701e+09
A124: =B28 -> Anua | B124: =D28 -> 20961 | C124: =E28 -> 1.4155911e+09 | E124: =INDEX($B$26:$B$117,MATCH(LARGE($F$26:$F$117,ROW()-121),$F$26:$F$117,0)) -> COSRX | F124: =LARGE($F$26:$F$117,ROW()-121) -> 3.3833846e+08
...

Sheet Meeting Prep
A1: H1 2026 REVIEW — MEETING PREP: WHAT YOU MUST KNOW
A2: MOARS (Netherlands) · Jan–Jun 2026 vs Jan–Jun 2025 · Revenue in KRW (converted amount) · Source: {worksheet} → see 'H1 Analysis' for detail
A4: 1. HEADLINE
A5: ="• Total revenue grew to "&TEXT('H1 Analysis'!C6/1000000,"#,##0")&"M KRW — "&TEXT('H1 Analysis'!E6,"+0.0%;-0.0%")&" YoY (from "&TEXT('H1 Analysis'!B6/1000000,"#,##0")&"M). This is the single biggest talking point." -> • Total revenue grew to 8,153M KRW — +80.3% YoY (from 4,523M). This is the single biggest talking point.
A6: ="• Gross profit "&TEXT('H1 Analysis'!C7/1000000,"#,##0")&"M KRW ("&TEXT('H1 Analysis'!E7,"+0.0%")&"); gross margin improved to "&TEXT('H1 Analysis'!C8,"0.0%")&" ("&TEXT('H1 Analysis'!D8*100,"+0.0;-0.0")&"pp) — growth was profitable, not just top-line." -> • Gross profit 1,893M KRW (+109.4%); gross margin improved to 23.2% (+3.2pp) — growth was profitable, not just top-line.
A7: ="• Units sold FELL "&TEXT(-'H1 Analysis'!E9,"0.0%")&" to "&TEXT('H1 Analysis'!C9,"#,##0")&" units while revenue rose 80% — a clear mix shift to higher-value brands/SKUs (higher average selling price). Expect a question on this." -> • Units sold FELL 14.1% to 807,407 units while revenue rose 80% — a clear mix shift to higher-value brands/SKUs (higher average selling price). Expect a question on this.
A8: ="• Order lines "&TEXT('H1 Analysis'!E10,"+0.0%")&" ("&'H1 Analysis'!B10&"→"&'H1 Analysis'!C10&"); active brands "&'H1 Analysis'!B11&"→"&'H1 Analysis'!C11&". Broader, more frequent ordering." -> • Order lines +65.0% (949→1566); active brands 59→63. Broader, more frequent ordering.
A10: 2. WHAT'S DRIVING GROWTH
A11: ="• medicube is the #1 growth engine: +"&TEXT('H1 Analysis'!F27/1000000,"#,##0")&"M KRW ("&TEXT('H1 Analysis'!G27,"+0%")&"), now the #2 brand overall at "&TEXT('H1 Analysis'!E27/1000000,"#,##0")&"M." -> • medicube is the #1 growth engine: +1,588M KRW (+405%), now the #2 brand overall at 1,981M.
A12: ="• Anua effectively launched as a full-sales brand: "&TEXT('H1 Analysis'!E28/1000000,"#,##0")&"M KRW in H1'26 vs virtually nil in H1'25 (sample-only prior). Now the #3 brand." -> • Anua effectively launched as a full-sales brand: 1,416M KRW in H1'26 vs virtually nil in H1'25 (sample-only prior). Now the #3 brand.
A13: • Second wave of breakout brands (all +250% or more): COSRX, Round Lab, BIODANCE, and Celimax (Celimax also carries the best margin among leaders at ~35%).
A14: • New brands introduced in H1'26 contributing real revenue: Arencia (~160M) and Dr.Rejuol (~137M), plus smaller additions (Lagom, G9SKIN).
A15: ="• Beauty of Joseon remains the anchor (#1 at "&TEXT('H1 Analysis'!E26/1000000,"#,##0")&"M) but growth is nearly flat ("&TEXT('H1 Analysis'!G26,"+0.0%")&"). It is holding share, not driving growth — watch for maturity/saturation." -> • Beauty of Joseon remains the anchor (#1 at 2,270M) but growth is nearly flat (+7.9%). It is holding share, not driving growth — watch for maturity/saturation.
A17: 3. RISKS & WATCH-OUTS
A18: ="• Revenue concentration is HIGH: top 3 brands (Beauty of Joseon, medicube, Anua) = "&TEXT(SUM('H1 Analysis'!E26:E28)/'H1 Analysis'!C6,"0%")&" of H1'26 revenue. A stumble in any one materially hits the total." -> • Revenue concentration is HIGH: top 3 brands (Beauty of Joseon, medicube, Anua) = 70% of H1'26 revenue. A stumble in any one materially hits the total.
A19: ="• Dr.Elsia collapsed: "&TEXT(INDEX('H1 Analysis'!$D$26:$D$117,MATCH("Dr.Elsia",'H1 Analysis'!$B$26:$B$117,0))/1000000,"#,##0")&"M → "&TEXT(INDEX('H1 Analysis'!$E$26:$E$117,MATCH("Dr.Elsia",'H1 Analysis'!$B$26:$B$117,0))/1000000,"#,##0")&"M KRW. It was the #2 brand in H1'25 — understand why (delisting? stock? demand?) before the meeting." -> • Dr.Elsia collapsed: 756M → 77M KRW. It was the #2 brand in H1'25 — understand why (delisting? stock? demand?) before the meeting.
A20: • Steep decliners & exits: VT Cosmetics -98%; brands that went to zero in H1'26 include JUMISO (~72M in H1'25), Axis-Y (~29M), MISSHA, W.DRESSROOM, Have Blue. Confirm these were intentional (discontinued) vs. lost business.
A21: ="• April was the only down month: "&TEXT('H1 Analysis'!D19,"0.0%")&" YoY. Every other month grew (Jan +384%, Jun +194%). Have an explanation ready for the April dip." -> • April was the only down month: -18.5% YoY. Every other month grew (Jan +384%, Jun +194%). Have an explanation ready for the April dip.
A22: • Growth leans on young/volatile brands (medicube, Anua, COSRX). High growth % comes off small H1'25 bases — sustainability into H2 is the key unknown.
A24: 4. FOC & SAMPLING
A25: ="• Free/promotional units cut sharply: "&TEXT('H1 Analysis'!B12,"#,##0")&" → "&TEXT('H1 Analysis'!C12,"#,##0")&" units ("&TEXT('H1 Analysis'!E12,"0.0%")&"). Far less product given away per KRW of sales." -> • Free/promotional units cut sharply: 36,542 → 7,223 units (-80.2%). Far less product given away per KRW of sales.
A26: • The MIX of free goods changed: H1'25 was almost entirely product samples (36,542 units, no FOC). H1'26 samples fell to 435 units, replaced by targeted FOC trade incentives (6,788 units).
A27: • H1'26 FOC (sales-incentive) units are concentrated in just 3 brands: Pyunkang Yul 3,750, Klavuu 2,550, Dr.Rejuol 488. Worth confirming the ROI / intent of these incentives.
A29: 5. QUESTIONS / TALKING POINTS FOR H2
A30: • Can medicube, Anua, COSRX, Round Lab, BIODANCE sustain momentum, or is this pipeline fill / one-off stocking?
A31: • Is the Dr.Elsia decline recoverable, and what replaces its H1'25 volume?
A32: • Given units down but revenue up — is this deliberate premiumization, or price/FX effects we should validate?
A33: • Reduce concentration risk: which mid-tier brands (Celimax, BIODANCE, Round Lab) should we push in H2?
A34: • H2'25 (Jul–Dec) was strong in the source data — set H2'26 targets against that comparable, not against H1.
A36: Data notes: All shipments are to one destination (Netherlands / MOARS). Revenue uses converted amount (환산금액, KRW); source amounts were stored as text and converted via helper columns AA:AF on {worksheet}. English brand names are best-effort mappings of the Korean source names (kept in 'H1 Analysis' col C for traceability).

Sheet 요약·특이점 (KR)
B1: MOARS 상반기 매출 요약 · 특이점 (2025 vs 2026)
B2: 고객사: MOARS (네덜란드) · 기간: 1~6월 · 매출: 환산금액(KRW) · 출처: {worksheet} · 상세: 'H1 Analysis' 참고
B4: 총매출 (H1'26, KRW) | F4: 매출총이익 (KRW) | J4: 이익률
B5: ='H1 Analysis'!C6 -> 8.1526898e+09 | F5: ='H1 Analysis'!C7 -> 1.8934963e+09 | J5: ='H1 Analysis'!C8 -> 0.23225418
B6: ="▲ "&TEXT('H1 Analysis'!E6,"0.0%")&" YoY" -> ▲ 80.3% YoY | F6: ="▲ "&TEXT('H1 Analysis'!E7,"0.0%")&" YoY" -> ▲ 109.4% YoY | J6: ="▲ "&TEXT('H1 Analysis'!D8,"0.0%")&"p" -> ▲ 3.2%p
B8: 판매수량 (개) | F8: 거래 건수 | J8: 무상수량 (샘플+FOC)
B9: ='H1 Analysis'!C9 -> 807407 | F9: ='H1 Analysis'!C10 -> 1566 | J9: ='H1 Analysis'!C12 -> 7223
B10: ="▼ "&TEXT('H1 Analysis'!E9,"0.0%")&" YoY" -> ▼ -14.1% YoY | F10: ="▲ "&TEXT('H1 Analysis'!E10,"0.0%")&" YoY" -> ▲ 65.0% YoY | J10: ="▼ "&TEXT('H1 Analysis'!E12,"0.0%")&" YoY" -> ▼ -80.2% YoY
B62: [차트 데이터 — H1'26 매출 구성]
B63: 브랜드 | C63: H1'26 매출
B64: ='H1 Analysis'!B26 -> Beauty of Joseon | C64: ='H1 Analysis'!E26 -> 2.2701934e+09
B65: ='H1 Analysis'!B27 -> medicube | C65: ='H1 Analysis'!E27 -> 1.9810588e+09
B66: ='H1 Analysis'!B28 -> Anua | C66: ='H1 Analysis'!E28 -> 1.4155911e+09
B67: ='H1 Analysis'!B29 -> COSRX | C67: ='H1 Analysis'!E29 -> 4.3602826e+08
B68: ='H1 Analysis'!B30 -> Round Lab | C68: ='H1 Analysis'!E30 -> 3.1603714e+08
B69: ='H1 Analysis'!B31 -> Celimax | C69: ='H1 Analysis'!E31 -> 2.8216878e+08
